[2023-08-22 17:17:56,902] {taskinstance.py:1179} INFO - Dependencies all met for <TaskInstance: entregable3.load_data_to_redshift manual__2023-08-22T17:07:18.568602+00:00 [queued]>
[2023-08-22 17:17:56,932] {taskinstance.py:1179} INFO - Dependencies all met for <TaskInstance: entregable3.load_data_to_redshift manual__2023-08-22T17:07:18.568602+00:00 [queued]>
[2023-08-22 17:17:56,937] {taskinstance.py:1376} INFO - 
--------------------------------------------------------------------------------
[2023-08-22 17:17:56,942] {taskinstance.py:1377} INFO - Starting attempt 1 of 6
[2023-08-22 17:17:56,946] {taskinstance.py:1378} INFO - 
--------------------------------------------------------------------------------
[2023-08-22 17:17:56,997] {taskinstance.py:1397} INFO - Executing <Task(PythonOperator): load_data_to_redshift> on 2023-08-22 17:07:18.568602+00:00
[2023-08-22 17:17:57,012] {standard_task_runner.py:79} INFO - Running: ['***', 'tasks', 'run', 'entregable3', 'load_data_to_redshift', 'manual__2023-08-22T17:07:18.568602+00:00', '--job-id', '63', '--raw', '--subdir', 'DAGS_FOLDER/entregable.py', '--cfg-path', '/tmp/tmp1_pvvylg', '--error-file', '/tmp/tmpo36nx0uc']
[2023-08-22 17:17:57,016] {standard_task_runner.py:80} INFO - Job 63: Subtask load_data_to_redshift
[2023-08-22 17:17:57,017] {standard_task_runner.py:52} INFO - Started process 14567 to run task
[2023-08-22 17:17:57,215] {task_command.py:371} INFO - Running <TaskInstance: entregable3.load_data_to_redshift manual__2023-08-22T17:07:18.568602+00:00 [running]> on host eebeded14cb4
[2023-08-22 17:17:57,398] {taskinstance.py:1591} INFO - Exporting the following env vars:
AIRFLOW_CTX_DAG_OWNER=Yamil
AIRFLOW_CTX_DAG_ID=entregable3
AIRFLOW_CTX_TASK_ID=load_data_to_redshift
AIRFLOW_CTX_EXECUTION_DATE=2023-08-22T17:07:18.568602+00:00
AIRFLOW_CTX_TRY_NUMBER=1
AIRFLOW_CTX_DAG_RUN_ID=manual__2023-08-22T17:07:18.568602+00:00
[2023-08-22 17:17:57,400] {taskinstance.py:1909} ERROR - Task failed with exception
Traceback (most recent call last):
  File "/home/airflow/.local/lib/python3.7/site-packages/airflow/operators/python.py", line 171, in execute
    return_value = self.execute_callable()
  File "/home/airflow/.local/lib/python3.7/site-packages/airflow/operators/python.py", line 189, in execute_callable
    return self.python_callable(*self.op_args, **self.op_kwargs)
  File "/opt/airflow/dags/entregable.py", line 55, in load
    df_transformed = df_final
NameError: name 'df_final' is not defined
[2023-08-22 17:17:57,439] {taskinstance.py:1420} INFO - Marking task as UP_FOR_RETRY. dag_id=entregable3, task_id=load_data_to_redshift, execution_date=20230822T170718, start_date=20230822T171756, end_date=20230822T171757
[2023-08-22 17:17:57,457] {standard_task_runner.py:97} ERROR - Failed to execute job 63 for task load_data_to_redshift (name 'df_final' is not defined; 14567)
[2023-08-22 17:17:57,478] {local_task_job.py:156} INFO - Task exited with return code 1
[2023-08-22 17:17:57,540] {local_task_job.py:273} INFO - 0 downstream tasks scheduled from follow-on schedule check
[2023-08-22 17:17:57,614] {dagrun.py:1081} ERROR - Failed to get task '<TaskInstance: entregable3.transform_data manual__2023-08-22T17:07:18.568602+00:00 [removed]>' for dag 'entregable3'. Marking it as removed.
[2023-08-22 17:17:57,616] {dagrun.py:1081} ERROR - Failed to get task '<TaskInstance: entregable3.get_data_from_api manual__2023-08-22T17:07:18.568602+00:00 [removed]>' for dag 'entregable3'. Marking it as removed.
