[2023-08-22 17:17:56,978] {taskinstance.py:1179} INFO - Dependencies all met for <TaskInstance: entregable3.load_data_to_redshift manual__2023-08-22T14:31:07.641022+00:00 [queued]>
[2023-08-22 17:17:57,048] {taskinstance.py:1179} INFO - Dependencies all met for <TaskInstance: entregable3.load_data_to_redshift manual__2023-08-22T14:31:07.641022+00:00 [queued]>
[2023-08-22 17:17:57,049] {taskinstance.py:1376} INFO - 
--------------------------------------------------------------------------------
[2023-08-22 17:17:57,051] {taskinstance.py:1377} INFO - Starting attempt 4 of 6
[2023-08-22 17:17:57,052] {taskinstance.py:1378} INFO - 
--------------------------------------------------------------------------------
[2023-08-22 17:17:57,122] {taskinstance.py:1397} INFO - Executing <Task(PythonOperator): load_data_to_redshift> on 2023-08-22 14:31:07.641022+00:00
[2023-08-22 17:17:57,134] {standard_task_runner.py:52} INFO - Started process 14568 to run task
[2023-08-22 17:17:57,149] {standard_task_runner.py:79} INFO - Running: ['***', 'tasks', 'run', 'entregable3', 'load_data_to_redshift', 'manual__2023-08-22T14:31:07.641022+00:00', '--job-id', '62', '--raw', '--subdir', 'DAGS_FOLDER/entregable.py', '--cfg-path', '/tmp/tmpspushh6w', '--error-file', '/tmp/tmpyv8k9i63']
[2023-08-22 17:17:57,156] {standard_task_runner.py:80} INFO - Job 62: Subtask load_data_to_redshift
[2023-08-22 17:17:57,369] {task_command.py:371} INFO - Running <TaskInstance: entregable3.load_data_to_redshift manual__2023-08-22T14:31:07.641022+00:00 [running]> on host eebeded14cb4
[2023-08-22 17:17:57,573] {taskinstance.py:1591} INFO - Exporting the following env vars:
AIRFLOW_CTX_DAG_OWNER=Yamil
AIRFLOW_CTX_DAG_ID=entregable3
AIRFLOW_CTX_TASK_ID=load_data_to_redshift
AIRFLOW_CTX_EXECUTION_DATE=2023-08-22T14:31:07.641022+00:00
AIRFLOW_CTX_TRY_NUMBER=4
AIRFLOW_CTX_DAG_RUN_ID=manual__2023-08-22T14:31:07.641022+00:00
[2023-08-22 17:17:57,593] {taskinstance.py:1909} ERROR - Task failed with exception
Traceback (most recent call last):
  File "/home/airflow/.local/lib/python3.7/site-packages/airflow/operators/python.py", line 171, in execute
    return_value = self.execute_callable()
  File "/home/airflow/.local/lib/python3.7/site-packages/airflow/operators/python.py", line 189, in execute_callable
    return self.python_callable(*self.op_args, **self.op_kwargs)
  File "/opt/airflow/dags/entregable.py", line 55, in load
    df_transformed = df_final
NameError: name 'df_final' is not defined
[2023-08-22 17:17:57,685] {taskinstance.py:1420} INFO - Marking task as UP_FOR_RETRY. dag_id=entregable3, task_id=load_data_to_redshift, execution_date=20230822T143107, start_date=20230822T171756, end_date=20230822T171757
[2023-08-22 17:17:57,743] {standard_task_runner.py:97} ERROR - Failed to execute job 62 for task load_data_to_redshift (name 'df_final' is not defined; 14568)
[2023-08-22 17:17:57,787] {local_task_job.py:156} INFO - Task exited with return code 1
[2023-08-22 17:17:57,890] {local_task_job.py:273} INFO - 0 downstream tasks scheduled from follow-on schedule check
[2023-08-22 17:17:57,936] {dagrun.py:1081} ERROR - Failed to get task '<TaskInstance: entregable3.transform_data manual__2023-08-22T14:31:07.641022+00:00 [removed]>' for dag 'entregable3'. Marking it as removed.
[2023-08-22 17:17:57,944] {dagrun.py:1081} ERROR - Failed to get task '<TaskInstance: entregable3.get_data_from_api manual__2023-08-22T14:31:07.641022+00:00 [removed]>' for dag 'entregable3'. Marking it as removed.
