[2023-08-22 17:44:18,035] {taskinstance.py:1179} INFO - Dependencies all met for <TaskInstance: entregable3.load_data_to_redshift manual__2023-08-22T17:24:49.622919+00:00 [queued]>
[2023-08-22 17:44:18,050] {taskinstance.py:1179} INFO - Dependencies all met for <TaskInstance: entregable3.load_data_to_redshift manual__2023-08-22T17:24:49.622919+00:00 [queued]>
[2023-08-22 17:44:18,050] {taskinstance.py:1376} INFO - 
--------------------------------------------------------------------------------
[2023-08-22 17:44:18,060] {taskinstance.py:1377} INFO - Starting attempt 1 of 6
[2023-08-22 17:44:18,061] {taskinstance.py:1378} INFO - 
--------------------------------------------------------------------------------
[2023-08-22 17:44:18,090] {taskinstance.py:1397} INFO - Executing <Task(PythonOperator): load_data_to_redshift> on 2023-08-22 17:24:49.622919+00:00
[2023-08-22 17:44:18,096] {standard_task_runner.py:52} INFO - Started process 15676 to run task
[2023-08-22 17:44:18,100] {standard_task_runner.py:79} INFO - Running: ['***', 'tasks', 'run', 'entregable3', 'load_data_to_redshift', 'manual__2023-08-22T17:24:49.622919+00:00', '--job-id', '83', '--raw', '--subdir', 'DAGS_FOLDER/entregable3.py', '--cfg-path', '/tmp/tmp8vr1dqtp', '--error-file', '/tmp/tmp8zal12dr']
[2023-08-22 17:44:18,102] {standard_task_runner.py:80} INFO - Job 83: Subtask load_data_to_redshift
[2023-08-22 17:44:18,185] {task_command.py:371} INFO - Running <TaskInstance: entregable3.load_data_to_redshift manual__2023-08-22T17:24:49.622919+00:00 [running]> on host eebeded14cb4
[2023-08-22 17:44:18,295] {taskinstance.py:1591} INFO - Exporting the following env vars:
AIRFLOW_CTX_DAG_OWNER=Yamil
AIRFLOW_CTX_DAG_ID=entregable3
AIRFLOW_CTX_TASK_ID=load_data_to_redshift
AIRFLOW_CTX_EXECUTION_DATE=2023-08-22T17:24:49.622919+00:00
AIRFLOW_CTX_TRY_NUMBER=1
AIRFLOW_CTX_DAG_RUN_ID=manual__2023-08-22T17:24:49.622919+00:00
[2023-08-22 17:44:18,297] {taskinstance.py:1909} ERROR - Task failed with exception
Traceback (most recent call last):
  File "/home/airflow/.local/lib/python3.7/site-packages/airflow/operators/python.py", line 171, in execute
    return_value = self.execute_callable()
  File "/home/airflow/.local/lib/python3.7/site-packages/airflow/operators/python.py", line 189, in execute_callable
    return self.python_callable(*self.op_args, **self.op_kwargs)
  File "/opt/airflow/dags/entregable3.py", line 51, in load
    df_transformed = df_final
NameError: name 'df_final' is not defined
[2023-08-22 17:44:18,313] {taskinstance.py:1420} INFO - Marking task as UP_FOR_RETRY. dag_id=entregable3, task_id=load_data_to_redshift, execution_date=20230822T172449, start_date=20230822T174418, end_date=20230822T174418
[2023-08-22 17:44:18,332] {standard_task_runner.py:97} ERROR - Failed to execute job 83 for task load_data_to_redshift (name 'df_final' is not defined; 15676)
[2023-08-22 17:44:18,351] {local_task_job.py:156} INFO - Task exited with return code 1
[2023-08-22 17:44:18,392] {local_task_job.py:273} INFO - 0 downstream tasks scheduled from follow-on schedule check
