[2023-08-21 19:31:51,723] {taskinstance.py:1179} INFO - Dependencies all met for <TaskInstance: entregable3.transform_data manual__2023-08-21T18:47:37.203083+00:00 [queued]>
[2023-08-21 19:31:51,744] {taskinstance.py:1179} INFO - Dependencies all met for <TaskInstance: entregable3.transform_data manual__2023-08-21T18:47:37.203083+00:00 [queued]>
[2023-08-21 19:31:51,745] {taskinstance.py:1376} INFO - 
--------------------------------------------------------------------------------
[2023-08-21 19:31:51,746] {taskinstance.py:1377} INFO - Starting attempt 2 of 6
[2023-08-21 19:31:51,747] {taskinstance.py:1378} INFO - 
--------------------------------------------------------------------------------
[2023-08-21 19:31:51,778] {taskinstance.py:1397} INFO - Executing <Task(PythonOperator): transform_data> on 2023-08-21 18:47:37.203083+00:00
[2023-08-21 19:31:51,793] {standard_task_runner.py:52} INFO - Started process 7045 to run task
[2023-08-21 19:31:51,803] {standard_task_runner.py:79} INFO - Running: ['***', 'tasks', 'run', 'entregable3', 'transform_data', 'manual__2023-08-21T18:47:37.203083+00:00', '--job-id', '19', '--raw', '--subdir', 'DAGS_FOLDER/entregable.py', '--cfg-path', '/tmp/tmpsjzlwiu6', '--error-file', '/tmp/tmpm6qavosv']
[2023-08-21 19:31:51,805] {standard_task_runner.py:80} INFO - Job 19: Subtask transform_data
[2023-08-21 19:31:51,922] {task_command.py:371} INFO - Running <TaskInstance: entregable3.transform_data manual__2023-08-21T18:47:37.203083+00:00 [running]> on host eebeded14cb4
[2023-08-21 19:31:52,070] {taskinstance.py:1591} INFO - Exporting the following env vars:
AIRFLOW_CTX_DAG_OWNER=Yamil
AIRFLOW_CTX_DAG_ID=entregable3
AIRFLOW_CTX_TASK_ID=transform_data
AIRFLOW_CTX_EXECUTION_DATE=2023-08-21T18:47:37.203083+00:00
AIRFLOW_CTX_TRY_NUMBER=2
AIRFLOW_CTX_DAG_RUN_ID=manual__2023-08-21T18:47:37.203083+00:00
[2023-08-21 19:31:52,083] {taskinstance.py:1909} ERROR - Task failed with exception
Traceback (most recent call last):
  File "/home/airflow/.local/lib/python3.7/site-packages/airflow/operators/python.py", line 171, in execute
    return_value = self.execute_callable()
  File "/home/airflow/.local/lib/python3.7/site-packages/airflow/operators/python.py", line 189, in execute_callable
    return self.python_callable(*self.op_args, **self.op_kwargs)
  File "/opt/airflow/dags/entregable.py", line 42, in transform
    nba_data_json = Variable.get("nba_data")
  File "/home/airflow/.local/lib/python3.7/site-packages/airflow/models/variable.py", line 138, in get
    raise KeyError(f'Variable {key} does not exist')
KeyError: 'Variable nba_data does not exist'
[2023-08-21 19:31:52,101] {taskinstance.py:1420} INFO - Marking task as UP_FOR_RETRY. dag_id=entregable3, task_id=transform_data, execution_date=20230821T184737, start_date=20230821T193151, end_date=20230821T193152
[2023-08-21 19:31:52,128] {standard_task_runner.py:97} ERROR - Failed to execute job 19 for task transform_data ('Variable nba_data does not exist'; 7045)
[2023-08-21 19:31:52,181] {local_task_job.py:156} INFO - Task exited with return code 1
[2023-08-21 19:31:52,253] {local_task_job.py:273} INFO - 0 downstream tasks scheduled from follow-on schedule check
