[2023-08-21 18:47:45,691] {taskinstance.py:1179} INFO - Dependencies all met for <TaskInstance: entregable3.transform_data manual__2023-08-21T18:47:37.203083+00:00 [queued]>
[2023-08-21 18:47:45,706] {taskinstance.py:1179} INFO - Dependencies all met for <TaskInstance: entregable3.transform_data manual__2023-08-21T18:47:37.203083+00:00 [queued]>
[2023-08-21 18:47:45,707] {taskinstance.py:1376} INFO - 
--------------------------------------------------------------------------------
[2023-08-21 18:47:45,711] {taskinstance.py:1377} INFO - Starting attempt 1 of 6
[2023-08-21 18:47:45,712] {taskinstance.py:1378} INFO - 
--------------------------------------------------------------------------------
[2023-08-21 18:47:45,749] {taskinstance.py:1397} INFO - Executing <Task(PythonOperator): transform_data> on 2023-08-21 18:47:37.203083+00:00
[2023-08-21 18:47:45,757] {standard_task_runner.py:52} INFO - Started process 4352 to run task
[2023-08-21 18:47:45,762] {standard_task_runner.py:79} INFO - Running: ['***', 'tasks', 'run', 'entregable3', 'transform_data', 'manual__2023-08-21T18:47:37.203083+00:00', '--job-id', '17', '--raw', '--subdir', 'DAGS_FOLDER/entregable.py', '--cfg-path', '/tmp/tmp62owurq3', '--error-file', '/tmp/tmpe804x5nf']
[2023-08-21 18:47:45,764] {standard_task_runner.py:80} INFO - Job 17: Subtask transform_data
[2023-08-21 18:47:45,863] {task_command.py:371} INFO - Running <TaskInstance: entregable3.transform_data manual__2023-08-21T18:47:37.203083+00:00 [running]> on host eebeded14cb4
[2023-08-21 18:47:45,976] {taskinstance.py:1591} INFO - Exporting the following env vars:
AIRFLOW_CTX_DAG_OWNER=Yamil
AIRFLOW_CTX_DAG_ID=entregable3
AIRFLOW_CTX_TASK_ID=transform_data
AIRFLOW_CTX_EXECUTION_DATE=2023-08-21T18:47:37.203083+00:00
AIRFLOW_CTX_TRY_NUMBER=1
AIRFLOW_CTX_DAG_RUN_ID=manual__2023-08-21T18:47:37.203083+00:00
[2023-08-21 18:47:45,978] {taskinstance.py:1909} ERROR - Task failed with exception
Traceback (most recent call last):
  File "/home/airflow/.local/lib/python3.7/site-packages/airflow/operators/python.py", line 171, in execute
    return_value = self.execute_callable()
  File "/home/airflow/.local/lib/python3.7/site-packages/airflow/operators/python.py", line 189, in execute_callable
    return self.python_callable(*self.op_args, **self.op_kwargs)
TypeError: transform() missing 1 required positional argument: 'all_data'
[2023-08-21 18:47:45,989] {taskinstance.py:1420} INFO - Marking task as UP_FOR_RETRY. dag_id=entregable3, task_id=transform_data, execution_date=20230821T184737, start_date=20230821T184745, end_date=20230821T184745
[2023-08-21 18:47:46,007] {standard_task_runner.py:97} ERROR - Failed to execute job 17 for task transform_data (transform() missing 1 required positional argument: 'all_data'; 4352)
[2023-08-21 18:47:46,055] {local_task_job.py:156} INFO - Task exited with return code 1
[2023-08-21 18:47:46,130] {local_task_job.py:273} INFO - 0 downstream tasks scheduled from follow-on schedule check
