[2023-08-25 17:57:54,038] {taskinstance.py:1179} INFO - Dependencies all met for <TaskInstance: entregable3.extract_and_transform_data manual__2023-08-25T17:57:52.320693+00:00 [queued]>
[2023-08-25 17:57:54,050] {taskinstance.py:1179} INFO - Dependencies all met for <TaskInstance: entregable3.extract_and_transform_data manual__2023-08-25T17:57:52.320693+00:00 [queued]>
[2023-08-25 17:57:54,051] {taskinstance.py:1376} INFO - 
--------------------------------------------------------------------------------
[2023-08-25 17:57:54,052] {taskinstance.py:1377} INFO - Starting attempt 1 of 6
[2023-08-25 17:57:54,052] {taskinstance.py:1378} INFO - 
--------------------------------------------------------------------------------
[2023-08-25 17:57:54,071] {taskinstance.py:1397} INFO - Executing <Task(PythonOperator): extract_and_transform_data> on 2023-08-25 17:57:52.320693+00:00
[2023-08-25 17:57:54,076] {standard_task_runner.py:52} INFO - Started process 1325 to run task
[2023-08-25 17:57:54,080] {standard_task_runner.py:79} INFO - Running: ['***', 'tasks', 'run', 'entregable3', 'extract_and_transform_data', 'manual__2023-08-25T17:57:52.320693+00:00', '--job-id', '96', '--raw', '--subdir', 'DAGS_FOLDER/entregable3.py', '--cfg-path', '/tmp/tmpmkhs8zp1', '--error-file', '/tmp/tmp64w6qkh_']
[2023-08-25 17:57:54,081] {standard_task_runner.py:80} INFO - Job 96: Subtask extract_and_transform_data
[2023-08-25 17:57:54,152] {task_command.py:371} INFO - Running <TaskInstance: entregable3.extract_and_transform_data manual__2023-08-25T17:57:52.320693+00:00 [running]> on host eebeded14cb4
[2023-08-25 17:57:54,277] {taskinstance.py:1591} INFO - Exporting the following env vars:
AIRFLOW_CTX_DAG_OWNER=Yamil
AIRFLOW_CTX_DAG_ID=entregable3
AIRFLOW_CTX_TASK_ID=extract_and_transform_data
AIRFLOW_CTX_EXECUTION_DATE=2023-08-25T17:57:52.320693+00:00
AIRFLOW_CTX_TRY_NUMBER=1
AIRFLOW_CTX_DAG_RUN_ID=manual__2023-08-25T17:57:52.320693+00:00
[2023-08-25 17:57:58,659] {taskinstance.py:1909} ERROR - Task failed with exception
Traceback (most recent call last):
  File "/home/airflow/.local/lib/python3.7/site-packages/airflow/operators/python.py", line 171, in execute
    return_value = self.execute_callable()
  File "/home/airflow/.local/lib/python3.7/site-packages/airflow/operators/python.py", line 189, in execute_callable
    return self.python_callable(*self.op_args, **self.op_kwargs)
  File "/opt/airflow/dags/funciones.py", line 156, in load
    load_data_to_redshift(df_final, table_name, schema_name, db_username, db_password, db_name, db_host, db_port)
  File "/opt/airflow/dags/funciones.py", line 103, in load_data_to_redshift
    engine = create_engine(f'postgresql://{db_username}:{db_password}@{db_host}:{db_port}/{db_name}')
  File "<string>", line 2, in create_engine
  File "/home/airflow/.local/lib/python3.7/site-packages/sqlalchemy/util/deprecations.py", line 309, in warned
    return fn(*args, **kwargs)
  File "/home/airflow/.local/lib/python3.7/site-packages/sqlalchemy/engine/create.py", line 530, in create_engine
    u = _url.make_url(url)
  File "/home/airflow/.local/lib/python3.7/site-packages/sqlalchemy/engine/url.py", line 715, in make_url
    return _parse_rfc1738_args(name_or_url)
  File "/home/airflow/.local/lib/python3.7/site-packages/sqlalchemy/engine/url.py", line 771, in _parse_rfc1738_args
    components["port"] = int(components["port"])
ValueError: invalid literal for int() with base 10: 'None'
[2023-08-25 17:57:58,679] {taskinstance.py:1420} INFO - Marking task as UP_FOR_RETRY. dag_id=entregable3, task_id=extract_and_transform_data, execution_date=20230825T175752, start_date=20230825T175754, end_date=20230825T175758
[2023-08-25 17:57:58,713] {standard_task_runner.py:97} ERROR - Failed to execute job 96 for task extract_and_transform_data (invalid literal for int() with base 10: 'None'; 1325)
[2023-08-25 17:57:58,726] {local_task_job.py:156} INFO - Task exited with return code 1
[2023-08-25 17:57:58,771] {local_task_job.py:273} INFO - 0 downstream tasks scheduled from follow-on schedule check
