[2023-08-22 14:09:34,131] {taskinstance.py:1179} INFO - Dependencies all met for <TaskInstance: entregable3.load_data_to_redshift manual__2023-08-22T14:09:25.186366+00:00 [queued]>
[2023-08-22 14:09:34,151] {taskinstance.py:1179} INFO - Dependencies all met for <TaskInstance: entregable3.load_data_to_redshift manual__2023-08-22T14:09:25.186366+00:00 [queued]>
[2023-08-22 14:09:34,159] {taskinstance.py:1376} INFO - 
--------------------------------------------------------------------------------
[2023-08-22 14:09:34,160] {taskinstance.py:1377} INFO - Starting attempt 1 of 6
[2023-08-22 14:09:34,160] {taskinstance.py:1378} INFO - 
--------------------------------------------------------------------------------
[2023-08-22 14:09:34,196] {taskinstance.py:1397} INFO - Executing <Task(PythonOperator): load_data_to_redshift> on 2023-08-22 14:09:25.186366+00:00
[2023-08-22 14:09:34,206] {standard_task_runner.py:52} INFO - Started process 2119 to run task
[2023-08-22 14:09:34,215] {standard_task_runner.py:79} INFO - Running: ['***', 'tasks', 'run', 'entregable3', 'load_data_to_redshift', 'manual__2023-08-22T14:09:25.186366+00:00', '--job-id', '26', '--raw', '--subdir', 'DAGS_FOLDER/entregable.py', '--cfg-path', '/tmp/tmpcmyu18q6', '--error-file', '/tmp/tmpygwrt2el']
[2023-08-22 14:09:34,217] {standard_task_runner.py:80} INFO - Job 26: Subtask load_data_to_redshift
[2023-08-22 14:09:34,330] {task_command.py:371} INFO - Running <TaskInstance: entregable3.load_data_to_redshift manual__2023-08-22T14:09:25.186366+00:00 [running]> on host eebeded14cb4
[2023-08-22 14:09:34,448] {taskinstance.py:1591} INFO - Exporting the following env vars:
AIRFLOW_CTX_DAG_OWNER=Yamil
AIRFLOW_CTX_DAG_ID=entregable3
AIRFLOW_CTX_TASK_ID=load_data_to_redshift
AIRFLOW_CTX_EXECUTION_DATE=2023-08-22T14:09:25.186366+00:00
AIRFLOW_CTX_TRY_NUMBER=1
AIRFLOW_CTX_DAG_RUN_ID=manual__2023-08-22T14:09:25.186366+00:00
[2023-08-22 14:09:34,449] {taskinstance.py:1909} ERROR - Task failed with exception
Traceback (most recent call last):
  File "/home/airflow/.local/lib/python3.7/site-packages/airflow/operators/python.py", line 171, in execute
    return_value = self.execute_callable()
  File "/home/airflow/.local/lib/python3.7/site-packages/airflow/operators/python.py", line 189, in execute_callable
    return self.python_callable(*self.op_args, **self.op_kwargs)
TypeError: load() missing 1 required positional argument: 'df_transformed'
[2023-08-22 14:09:34,466] {taskinstance.py:1420} INFO - Marking task as UP_FOR_RETRY. dag_id=entregable3, task_id=load_data_to_redshift, execution_date=20230822T140925, start_date=20230822T140934, end_date=20230822T140934
[2023-08-22 14:09:34,487] {standard_task_runner.py:97} ERROR - Failed to execute job 26 for task load_data_to_redshift (load() missing 1 required positional argument: 'df_transformed'; 2119)
[2023-08-22 14:09:34,504] {local_task_job.py:156} INFO - Task exited with return code 1
[2023-08-22 14:09:34,583] {local_task_job.py:273} INFO - 0 downstream tasks scheduled from follow-on schedule check
