[2023-08-22 14:28:39,223] {taskinstance.py:1179} INFO - Dependencies all met for <TaskInstance: entregable3.load_data_to_redshift manual__2023-08-22T14:09:25.186366+00:00 [queued]>
[2023-08-22 14:28:39,242] {taskinstance.py:1179} INFO - Dependencies all met for <TaskInstance: entregable3.load_data_to_redshift manual__2023-08-22T14:09:25.186366+00:00 [queued]>
[2023-08-22 14:28:39,242] {taskinstance.py:1376} INFO - 
--------------------------------------------------------------------------------
[2023-08-22 14:28:39,243] {taskinstance.py:1377} INFO - Starting attempt 2 of 6
[2023-08-22 14:28:39,244] {taskinstance.py:1378} INFO - 
--------------------------------------------------------------------------------
[2023-08-22 14:28:39,270] {taskinstance.py:1397} INFO - Executing <Task(PythonOperator): load_data_to_redshift> on 2023-08-22 14:09:25.186366+00:00
[2023-08-22 14:28:39,280] {standard_task_runner.py:52} INFO - Started process 3303 to run task
[2023-08-22 14:28:39,296] {standard_task_runner.py:79} INFO - Running: ['***', 'tasks', 'run', 'entregable3', 'load_data_to_redshift', 'manual__2023-08-22T14:09:25.186366+00:00', '--job-id', '28', '--raw', '--subdir', 'DAGS_FOLDER/entregable.py', '--cfg-path', '/tmp/tmpoc8ooqer', '--error-file', '/tmp/tmpfcxl6v52']
[2023-08-22 14:28:39,298] {standard_task_runner.py:80} INFO - Job 28: Subtask load_data_to_redshift
[2023-08-22 14:28:39,435] {task_command.py:371} INFO - Running <TaskInstance: entregable3.load_data_to_redshift manual__2023-08-22T14:09:25.186366+00:00 [running]> on host eebeded14cb4
[2023-08-22 14:28:39,567] {taskinstance.py:1591} INFO - Exporting the following env vars:
AIRFLOW_CTX_DAG_OWNER=Yamil
AIRFLOW_CTX_DAG_ID=entregable3
AIRFLOW_CTX_TASK_ID=load_data_to_redshift
AIRFLOW_CTX_EXECUTION_DATE=2023-08-22T14:09:25.186366+00:00
AIRFLOW_CTX_TRY_NUMBER=2
AIRFLOW_CTX_DAG_RUN_ID=manual__2023-08-22T14:09:25.186366+00:00
[2023-08-22 14:28:39,571] {taskinstance.py:1909} ERROR - Task failed with exception
Traceback (most recent call last):
  File "/home/airflow/.local/lib/python3.7/site-packages/airflow/operators/python.py", line 171, in execute
    return_value = self.execute_callable()
  File "/home/airflow/.local/lib/python3.7/site-packages/airflow/operators/python.py", line 189, in execute_callable
    return self.python_callable(*self.op_args, **self.op_kwargs)
TypeError: load() missing 1 required positional argument: 'df_transformed'
[2023-08-22 14:28:39,582] {taskinstance.py:1420} INFO - Marking task as UP_FOR_RETRY. dag_id=entregable3, task_id=load_data_to_redshift, execution_date=20230822T140925, start_date=20230822T142839, end_date=20230822T142839
[2023-08-22 14:28:39,601] {standard_task_runner.py:97} ERROR - Failed to execute job 28 for task load_data_to_redshift (load() missing 1 required positional argument: 'df_transformed'; 3303)
[2023-08-22 14:28:39,622] {local_task_job.py:156} INFO - Task exited with return code 1
[2023-08-22 14:28:39,691] {local_task_job.py:273} INFO - 0 downstream tasks scheduled from follow-on schedule check
