[2023-08-22 17:18:36,018] {taskinstance.py:1179} INFO - Dependencies all met for <TaskInstance: entregable3.get_data_from_api manual__2023-08-22T14:36:35.688963+00:00 [queued]>
[2023-08-22 17:18:36,089] {taskinstance.py:1179} INFO - Dependencies all met for <TaskInstance: entregable3.get_data_from_api manual__2023-08-22T14:36:35.688963+00:00 [queued]>
[2023-08-22 17:18:36,112] {taskinstance.py:1376} INFO - 
--------------------------------------------------------------------------------
[2023-08-22 17:18:36,115] {taskinstance.py:1377} INFO - Starting attempt 2 of 6
[2023-08-22 17:18:36,116] {taskinstance.py:1378} INFO - 
--------------------------------------------------------------------------------
[2023-08-22 17:18:36,203] {taskinstance.py:1397} INFO - Executing <Task(PythonOperator): get_data_from_api> on 2023-08-22 14:36:35.688963+00:00
[2023-08-22 17:18:36,242] {standard_task_runner.py:79} INFO - Running: ['***', 'tasks', 'run', 'entregable3', 'get_data_from_api', 'manual__2023-08-22T14:36:35.688963+00:00', '--job-id', '74', '--raw', '--subdir', 'DAGS_FOLDER/entregable3.py', '--cfg-path', '/tmp/tmpdi9u4jv8', '--error-file', '/tmp/tmpczph_7us']
[2023-08-22 17:18:36,245] {standard_task_runner.py:80} INFO - Job 74: Subtask get_data_from_api
[2023-08-22 17:18:36,215] {standard_task_runner.py:52} INFO - Started process 14650 to run task
[2023-08-22 17:18:36,650] {task_command.py:371} INFO - Running <TaskInstance: entregable3.get_data_from_api manual__2023-08-22T14:36:35.688963+00:00 [running]> on host eebeded14cb4
[2023-08-22 17:18:37,033] {taskinstance.py:1591} INFO - Exporting the following env vars:
AIRFLOW_CTX_DAG_OWNER=Yamil
AIRFLOW_CTX_DAG_ID=entregable3
AIRFLOW_CTX_TASK_ID=get_data_from_api
AIRFLOW_CTX_EXECUTION_DATE=2023-08-22T14:36:35.688963+00:00
AIRFLOW_CTX_TRY_NUMBER=2
AIRFLOW_CTX_DAG_RUN_ID=manual__2023-08-22T14:36:35.688963+00:00
[2023-08-22 17:18:37,034] {taskinstance.py:1909} ERROR - Task failed with exception
Traceback (most recent call last):
  File "/home/airflow/.local/lib/python3.7/site-packages/airflow/operators/python.py", line 171, in execute
    return_value = self.execute_callable()
  File "/home/airflow/.local/lib/python3.7/site-packages/airflow/operators/python.py", line 189, in execute_callable
    return self.python_callable(*self.op_args, **self.op_kwargs)
TypeError: get_data_from_api() missing 1 required positional argument: 'url'
[2023-08-22 17:18:37,081] {taskinstance.py:1420} INFO - Marking task as UP_FOR_RETRY. dag_id=entregable3, task_id=get_data_from_api, execution_date=20230822T143635, start_date=20230822T171836, end_date=20230822T171837
[2023-08-22 17:18:37,149] {standard_task_runner.py:97} ERROR - Failed to execute job 74 for task get_data_from_api (get_data_from_api() missing 1 required positional argument: 'url'; 14650)
[2023-08-22 17:18:37,175] {local_task_job.py:156} INFO - Task exited with return code 1
[2023-08-22 17:18:37,321] {dagrun.py:1081} ERROR - Failed to get task '<TaskInstance: entregable3.extract_and_transform_data manual__2023-08-22T14:36:35.688963+00:00 [removed]>' for dag 'entregable3'. Marking it as removed.
[2023-08-22 17:18:37,358] {local_task_job.py:273} INFO - 0 downstream tasks scheduled from follow-on schedule check
