[2023-08-22 17:07:21,339] {taskinstance.py:1179} INFO - Dependencies all met for <TaskInstance: entregable3.get_data_from_api manual__2023-08-22T17:07:18.568602+00:00 [queued]>
[2023-08-22 17:07:21,355] {taskinstance.py:1179} INFO - Dependencies all met for <TaskInstance: entregable3.get_data_from_api manual__2023-08-22T17:07:18.568602+00:00 [queued]>
[2023-08-22 17:07:21,356] {taskinstance.py:1376} INFO - 
--------------------------------------------------------------------------------
[2023-08-22 17:07:21,357] {taskinstance.py:1377} INFO - Starting attempt 1 of 6
[2023-08-22 17:07:21,357] {taskinstance.py:1378} INFO - 
--------------------------------------------------------------------------------
[2023-08-22 17:07:21,413] {taskinstance.py:1397} INFO - Executing <Task(PythonOperator): get_data_from_api> on 2023-08-22 17:07:18.568602+00:00
[2023-08-22 17:07:21,421] {standard_task_runner.py:52} INFO - Started process 13526 to run task
[2023-08-22 17:07:21,432] {standard_task_runner.py:79} INFO - Running: ['***', 'tasks', 'run', 'entregable3', 'get_data_from_api', 'manual__2023-08-22T17:07:18.568602+00:00', '--job-id', '48', '--raw', '--subdir', 'DAGS_FOLDER/entregable3.py', '--cfg-path', '/tmp/tmplosr7ht0', '--error-file', '/tmp/tmpf0ttwxk7']
[2023-08-22 17:07:21,437] {standard_task_runner.py:80} INFO - Job 48: Subtask get_data_from_api
[2023-08-22 17:07:21,554] {task_command.py:371} INFO - Running <TaskInstance: entregable3.get_data_from_api manual__2023-08-22T17:07:18.568602+00:00 [running]> on host eebeded14cb4
[2023-08-22 17:07:21,761] {taskinstance.py:1591} INFO - Exporting the following env vars:
AIRFLOW_CTX_DAG_OWNER=Yamil
AIRFLOW_CTX_DAG_ID=entregable3
AIRFLOW_CTX_TASK_ID=get_data_from_api
AIRFLOW_CTX_EXECUTION_DATE=2023-08-22T17:07:18.568602+00:00
AIRFLOW_CTX_TRY_NUMBER=1
AIRFLOW_CTX_DAG_RUN_ID=manual__2023-08-22T17:07:18.568602+00:00
[2023-08-22 17:07:21,764] {taskinstance.py:1909} ERROR - Task failed with exception
Traceback (most recent call last):
  File "/home/airflow/.local/lib/python3.7/site-packages/airflow/operators/python.py", line 171, in execute
    return_value = self.execute_callable()
  File "/home/airflow/.local/lib/python3.7/site-packages/airflow/operators/python.py", line 189, in execute_callable
    return self.python_callable(*self.op_args, **self.op_kwargs)
TypeError: get_data_from_api() missing 1 required positional argument: 'url'
[2023-08-22 17:07:21,778] {taskinstance.py:1420} INFO - Marking task as UP_FOR_RETRY. dag_id=entregable3, task_id=get_data_from_api, execution_date=20230822T170718, start_date=20230822T170721, end_date=20230822T170721
[2023-08-22 17:07:21,802] {standard_task_runner.py:97} ERROR - Failed to execute job 48 for task get_data_from_api (get_data_from_api() missing 1 required positional argument: 'url'; 13526)
[2023-08-22 17:07:21,850] {local_task_job.py:156} INFO - Task exited with return code 1
[2023-08-22 17:07:21,941] {local_task_job.py:273} INFO - 0 downstream tasks scheduled from follow-on schedule check
