[2023-08-22 17:09:44,418] {taskinstance.py:1179} INFO - Dependencies all met for <TaskInstance: entregable3.get_data_from_api manual__2023-08-22T17:09:42.756429+00:00 [queued]>
[2023-08-22 17:09:44,430] {taskinstance.py:1179} INFO - Dependencies all met for <TaskInstance: entregable3.get_data_from_api manual__2023-08-22T17:09:42.756429+00:00 [queued]>
[2023-08-22 17:09:44,431] {taskinstance.py:1376} INFO - 
--------------------------------------------------------------------------------
[2023-08-22 17:09:44,433] {taskinstance.py:1377} INFO - Starting attempt 1 of 6
[2023-08-22 17:09:44,433] {taskinstance.py:1378} INFO - 
--------------------------------------------------------------------------------
[2023-08-22 17:09:44,456] {taskinstance.py:1397} INFO - Executing <Task(PythonOperator): get_data_from_api> on 2023-08-22 17:09:42.756429+00:00
[2023-08-22 17:09:44,462] {standard_task_runner.py:52} INFO - Started process 13746 to run task
[2023-08-22 17:09:44,469] {standard_task_runner.py:79} INFO - Running: ['***', 'tasks', 'run', 'entregable3', 'get_data_from_api', 'manual__2023-08-22T17:09:42.756429+00:00', '--job-id', '49', '--raw', '--subdir', 'DAGS_FOLDER/entregable3.py', '--cfg-path', '/tmp/tmp8v13c88g', '--error-file', '/tmp/tmp49k5lcjq']
[2023-08-22 17:09:44,472] {standard_task_runner.py:80} INFO - Job 49: Subtask get_data_from_api
[2023-08-22 17:09:44,581] {task_command.py:371} INFO - Running <TaskInstance: entregable3.get_data_from_api manual__2023-08-22T17:09:42.756429+00:00 [running]> on host eebeded14cb4
[2023-08-22 17:09:44,716] {taskinstance.py:1591} INFO - Exporting the following env vars:
AIRFLOW_CTX_DAG_OWNER=Yamil
AIRFLOW_CTX_DAG_ID=entregable3
AIRFLOW_CTX_TASK_ID=get_data_from_api
AIRFLOW_CTX_EXECUTION_DATE=2023-08-22T17:09:42.756429+00:00
AIRFLOW_CTX_TRY_NUMBER=1
AIRFLOW_CTX_DAG_RUN_ID=manual__2023-08-22T17:09:42.756429+00:00
[2023-08-22 17:09:44,720] {taskinstance.py:1909} ERROR - Task failed with exception
Traceback (most recent call last):
  File "/home/airflow/.local/lib/python3.7/site-packages/airflow/operators/python.py", line 171, in execute
    return_value = self.execute_callable()
  File "/home/airflow/.local/lib/python3.7/site-packages/airflow/operators/python.py", line 189, in execute_callable
    return self.python_callable(*self.op_args, **self.op_kwargs)
TypeError: get_data_from_api() missing 1 required positional argument: 'url'
[2023-08-22 17:09:44,734] {taskinstance.py:1420} INFO - Marking task as UP_FOR_RETRY. dag_id=entregable3, task_id=get_data_from_api, execution_date=20230822T170942, start_date=20230822T170944, end_date=20230822T170944
[2023-08-22 17:09:44,753] {standard_task_runner.py:97} ERROR - Failed to execute job 49 for task get_data_from_api (get_data_from_api() missing 1 required positional argument: 'url'; 13746)
[2023-08-22 17:09:44,766] {local_task_job.py:156} INFO - Task exited with return code 1
[2023-08-22 17:09:44,854] {local_task_job.py:273} INFO - 0 downstream tasks scheduled from follow-on schedule check
