[2023-08-22 17:24:51,366] {taskinstance.py:1179} INFO - Dependencies all met for <TaskInstance: entregable3.get_data_from_api manual__2023-08-22T17:24:49.622919+00:00 [queued]>
[2023-08-22 17:24:51,379] {taskinstance.py:1179} INFO - Dependencies all met for <TaskInstance: entregable3.get_data_from_api manual__2023-08-22T17:24:49.622919+00:00 [queued]>
[2023-08-22 17:24:51,379] {taskinstance.py:1376} INFO - 
--------------------------------------------------------------------------------
[2023-08-22 17:24:51,381] {taskinstance.py:1377} INFO - Starting attempt 1 of 6
[2023-08-22 17:24:51,382] {taskinstance.py:1378} INFO - 
--------------------------------------------------------------------------------
[2023-08-22 17:24:51,399] {taskinstance.py:1397} INFO - Executing <Task(PythonOperator): get_data_from_api> on 2023-08-22 17:24:49.622919+00:00
[2023-08-22 17:24:51,404] {standard_task_runner.py:52} INFO - Started process 15004 to run task
[2023-08-22 17:24:51,408] {standard_task_runner.py:79} INFO - Running: ['***', 'tasks', 'run', 'entregable3', 'get_data_from_api', 'manual__2023-08-22T17:24:49.622919+00:00', '--job-id', '78', '--raw', '--subdir', 'DAGS_FOLDER/entregable3.py', '--cfg-path', '/tmp/tmpmh_qtiuj', '--error-file', '/tmp/tmp4xqnlk5c']
[2023-08-22 17:24:51,410] {standard_task_runner.py:80} INFO - Job 78: Subtask get_data_from_api
[2023-08-22 17:24:51,490] {task_command.py:371} INFO - Running <TaskInstance: entregable3.get_data_from_api manual__2023-08-22T17:24:49.622919+00:00 [running]> on host eebeded14cb4
[2023-08-22 17:24:51,593] {taskinstance.py:1591} INFO - Exporting the following env vars:
AIRFLOW_CTX_DAG_OWNER=Yamil
AIRFLOW_CTX_DAG_ID=entregable3
AIRFLOW_CTX_TASK_ID=get_data_from_api
AIRFLOW_CTX_EXECUTION_DATE=2023-08-22T17:24:49.622919+00:00
AIRFLOW_CTX_TRY_NUMBER=1
AIRFLOW_CTX_DAG_RUN_ID=manual__2023-08-22T17:24:49.622919+00:00
[2023-08-22 17:24:51,595] {taskinstance.py:1909} ERROR - Task failed with exception
Traceback (most recent call last):
  File "/home/airflow/.local/lib/python3.7/site-packages/airflow/operators/python.py", line 171, in execute
    return_value = self.execute_callable()
  File "/home/airflow/.local/lib/python3.7/site-packages/airflow/operators/python.py", line 189, in execute_callable
    return self.python_callable(*self.op_args, **self.op_kwargs)
TypeError: get_data_from_api() missing 1 required positional argument: 'url'
[2023-08-22 17:24:51,607] {taskinstance.py:1420} INFO - Marking task as UP_FOR_RETRY. dag_id=entregable3, task_id=get_data_from_api, execution_date=20230822T172449, start_date=20230822T172451, end_date=20230822T172451
[2023-08-22 17:24:51,626] {standard_task_runner.py:97} ERROR - Failed to execute job 78 for task get_data_from_api (get_data_from_api() missing 1 required positional argument: 'url'; 15004)
[2023-08-22 17:24:51,660] {local_task_job.py:156} INFO - Task exited with return code 1
[2023-08-22 17:24:51,744] {local_task_job.py:273} INFO - 0 downstream tasks scheduled from follow-on schedule check
