[2023-08-22 14:53:04,905] {taskinstance.py:1179} INFO - Dependencies all met for <TaskInstance: entregable3.load_data_to_redshift manual__2023-08-22T13:44:58.673932+00:00 [queued]>
[2023-08-22 14:53:04,932] {taskinstance.py:1179} INFO - Dependencies all met for <TaskInstance: entregable3.load_data_to_redshift manual__2023-08-22T13:44:58.673932+00:00 [queued]>
[2023-08-22 14:53:04,933] {taskinstance.py:1376} INFO - 
--------------------------------------------------------------------------------
[2023-08-22 14:53:04,937] {taskinstance.py:1377} INFO - Starting attempt 4 of 6
[2023-08-22 14:53:04,938] {taskinstance.py:1378} INFO - 
--------------------------------------------------------------------------------
[2023-08-22 14:53:04,977] {taskinstance.py:1397} INFO - Executing <Task(PythonOperator): load_data_to_redshift> on 2023-08-22 13:44:58.673932+00:00
[2023-08-22 14:53:04,982] {standard_task_runner.py:52} INFO - Started process 4847 to run task
[2023-08-22 14:53:04,986] {standard_task_runner.py:79} INFO - Running: ['***', 'tasks', 'run', 'entregable3', 'load_data_to_redshift', 'manual__2023-08-22T13:44:58.673932+00:00', '--job-id', '39', '--raw', '--subdir', 'DAGS_FOLDER/entregable.py', '--cfg-path', '/tmp/tmpn6vt9fmx', '--error-file', '/tmp/tmpqlxk3fkv']
[2023-08-22 14:53:04,989] {standard_task_runner.py:80} INFO - Job 39: Subtask load_data_to_redshift
[2023-08-22 14:53:05,135] {task_command.py:371} INFO - Running <TaskInstance: entregable3.load_data_to_redshift manual__2023-08-22T13:44:58.673932+00:00 [running]> on host eebeded14cb4
[2023-08-22 14:53:05,275] {taskinstance.py:1591} INFO - Exporting the following env vars:
AIRFLOW_CTX_DAG_OWNER=Yamil
AIRFLOW_CTX_DAG_ID=entregable3
AIRFLOW_CTX_TASK_ID=load_data_to_redshift
AIRFLOW_CTX_EXECUTION_DATE=2023-08-22T13:44:58.673932+00:00
AIRFLOW_CTX_TRY_NUMBER=4
AIRFLOW_CTX_DAG_RUN_ID=manual__2023-08-22T13:44:58.673932+00:00
[2023-08-22 14:53:05,280] {taskinstance.py:1909} ERROR - Task failed with exception
Traceback (most recent call last):
  File "/home/airflow/.local/lib/python3.7/site-packages/airflow/operators/python.py", line 171, in execute
    return_value = self.execute_callable()
  File "/home/airflow/.local/lib/python3.7/site-packages/airflow/operators/python.py", line 189, in execute_callable
    return self.python_callable(*self.op_args, **self.op_kwargs)
TypeError: load() missing 1 required positional argument: 'df_transformed'
[2023-08-22 14:53:05,292] {taskinstance.py:1420} INFO - Marking task as UP_FOR_RETRY. dag_id=entregable3, task_id=load_data_to_redshift, execution_date=20230822T134458, start_date=20230822T145304, end_date=20230822T145305
[2023-08-22 14:53:05,325] {standard_task_runner.py:97} ERROR - Failed to execute job 39 for task load_data_to_redshift (load() missing 1 required positional argument: 'df_transformed'; 4847)
[2023-08-22 14:53:05,370] {local_task_job.py:156} INFO - Task exited with return code 1
[2023-08-22 14:53:05,433] {local_task_job.py:273} INFO - 0 downstream tasks scheduled from follow-on schedule check
