[2023-08-22 14:36:35,283] {taskinstance.py:1179} INFO - Dependencies all met for <TaskInstance: entregable3.load_data_to_redshift manual__2023-08-22T13:44:58.673932+00:00 [queued]>
[2023-08-22 14:36:35,301] {taskinstance.py:1179} INFO - Dependencies all met for <TaskInstance: entregable3.load_data_to_redshift manual__2023-08-22T13:44:58.673932+00:00 [queued]>
[2023-08-22 14:36:35,301] {taskinstance.py:1376} INFO - 
--------------------------------------------------------------------------------
[2023-08-22 14:36:35,302] {taskinstance.py:1377} INFO - Starting attempt 3 of 6
[2023-08-22 14:36:35,304] {taskinstance.py:1378} INFO - 
--------------------------------------------------------------------------------
[2023-08-22 14:36:35,338] {taskinstance.py:1397} INFO - Executing <Task(PythonOperator): load_data_to_redshift> on 2023-08-22 13:44:58.673932+00:00
[2023-08-22 14:36:35,348] {standard_task_runner.py:52} INFO - Started process 3814 to run task
[2023-08-22 14:36:35,356] {standard_task_runner.py:79} INFO - Running: ['***', 'tasks', 'run', 'entregable3', 'load_data_to_redshift', 'manual__2023-08-22T13:44:58.673932+00:00', '--job-id', '33', '--raw', '--subdir', 'DAGS_FOLDER/entregable.py', '--cfg-path', '/tmp/tmpzmg1daqm', '--error-file', '/tmp/tmplmyz3g_a']
[2023-08-22 14:36:35,360] {standard_task_runner.py:80} INFO - Job 33: Subtask load_data_to_redshift
[2023-08-22 14:36:35,481] {task_command.py:371} INFO - Running <TaskInstance: entregable3.load_data_to_redshift manual__2023-08-22T13:44:58.673932+00:00 [running]> on host eebeded14cb4
[2023-08-22 14:36:35,631] {taskinstance.py:1591} INFO - Exporting the following env vars:
AIRFLOW_CTX_DAG_OWNER=Yamil
AIRFLOW_CTX_DAG_ID=entregable3
AIRFLOW_CTX_TASK_ID=load_data_to_redshift
AIRFLOW_CTX_EXECUTION_DATE=2023-08-22T13:44:58.673932+00:00
AIRFLOW_CTX_TRY_NUMBER=3
AIRFLOW_CTX_DAG_RUN_ID=manual__2023-08-22T13:44:58.673932+00:00
[2023-08-22 14:36:39,079] {taskinstance.py:1909} ERROR - Task failed with exception
Traceback (most recent call last):
  File "/home/airflow/.local/lib/python3.7/site-packages/airflow/operators/python.py", line 171, in execute
    return_value = self.execute_callable()
  File "/home/airflow/.local/lib/python3.7/site-packages/airflow/operators/python.py", line 189, in execute_callable
    return self.python_callable(*self.op_args, **self.op_kwargs)
  File "/opt/airflow/dags/entregable.py", line 67, in load
    load_data_to_redshift(df_transformed, table_name, schema_name, db_username, db_password, db_name, db_host, db_port)
  File "/opt/airflow/dags/funciones.py", line 96, in load_data_to_redshift
    df_no_duplicates = df_final[~df_final['id'].isin(existing_ids)]
TypeError: 'NoneType' object is not subscriptable
[2023-08-22 14:36:39,152] {taskinstance.py:1420} INFO - Marking task as UP_FOR_RETRY. dag_id=entregable3, task_id=load_data_to_redshift, execution_date=20230822T134458, start_date=20230822T143635, end_date=20230822T143639
[2023-08-22 14:36:39,196] {standard_task_runner.py:97} ERROR - Failed to execute job 33 for task load_data_to_redshift ('NoneType' object is not subscriptable; 3814)
[2023-08-22 14:36:39,239] {local_task_job.py:156} INFO - Task exited with return code 1
[2023-08-22 14:36:39,311] {local_task_job.py:273} INFO - 0 downstream tasks scheduled from follow-on schedule check
