[2023-08-22 14:53:05,033] {taskinstance.py:1179} INFO - Dependencies all met for <TaskInstance: entregable3.load_data_to_redshift manual__2023-08-22T14:36:35.688963+00:00 [queued]>
[2023-08-22 14:53:05,081] {taskinstance.py:1179} INFO - Dependencies all met for <TaskInstance: entregable3.load_data_to_redshift manual__2023-08-22T14:36:35.688963+00:00 [queued]>
[2023-08-22 14:53:05,093] {taskinstance.py:1376} INFO - 
--------------------------------------------------------------------------------
[2023-08-22 14:53:05,095] {taskinstance.py:1377} INFO - Starting attempt 2 of 6
[2023-08-22 14:53:05,096] {taskinstance.py:1378} INFO - 
--------------------------------------------------------------------------------
[2023-08-22 14:53:05,136] {taskinstance.py:1397} INFO - Executing <Task(PythonOperator): load_data_to_redshift> on 2023-08-22 14:36:35.688963+00:00
[2023-08-22 14:53:05,145] {standard_task_runner.py:52} INFO - Started process 4849 to run task
[2023-08-22 14:53:05,156] {standard_task_runner.py:79} INFO - Running: ['***', 'tasks', 'run', 'entregable3', 'load_data_to_redshift', 'manual__2023-08-22T14:36:35.688963+00:00', '--job-id', '41', '--raw', '--subdir', 'DAGS_FOLDER/entregable.py', '--cfg-path', '/tmp/tmpc72bqbpz', '--error-file', '/tmp/tmp8rdbe7fz']
[2023-08-22 14:53:05,158] {standard_task_runner.py:80} INFO - Job 41: Subtask load_data_to_redshift
[2023-08-22 14:53:05,296] {task_command.py:371} INFO - Running <TaskInstance: entregable3.load_data_to_redshift manual__2023-08-22T14:36:35.688963+00:00 [running]> on host eebeded14cb4
[2023-08-22 14:53:05,431] {taskinstance.py:1591} INFO - Exporting the following env vars:
AIRFLOW_CTX_DAG_OWNER=Yamil
AIRFLOW_CTX_DAG_ID=entregable3
AIRFLOW_CTX_TASK_ID=load_data_to_redshift
AIRFLOW_CTX_EXECUTION_DATE=2023-08-22T14:36:35.688963+00:00
AIRFLOW_CTX_TRY_NUMBER=2
AIRFLOW_CTX_DAG_RUN_ID=manual__2023-08-22T14:36:35.688963+00:00
[2023-08-22 14:53:05,435] {taskinstance.py:1909} ERROR - Task failed with exception
Traceback (most recent call last):
  File "/home/airflow/.local/lib/python3.7/site-packages/airflow/operators/python.py", line 171, in execute
    return_value = self.execute_callable()
  File "/home/airflow/.local/lib/python3.7/site-packages/airflow/operators/python.py", line 189, in execute_callable
    return self.python_callable(*self.op_args, **self.op_kwargs)
TypeError: load() missing 1 required positional argument: 'df_transformed'
[2023-08-22 14:53:05,448] {taskinstance.py:1420} INFO - Marking task as UP_FOR_RETRY. dag_id=entregable3, task_id=load_data_to_redshift, execution_date=20230822T143635, start_date=20230822T145305, end_date=20230822T145305
[2023-08-22 14:53:05,467] {standard_task_runner.py:97} ERROR - Failed to execute job 41 for task load_data_to_redshift (load() missing 1 required positional argument: 'df_transformed'; 4849)
[2023-08-22 14:53:05,498] {local_task_job.py:156} INFO - Task exited with return code 1
[2023-08-22 14:53:05,555] {local_task_job.py:273} INFO - 0 downstream tasks scheduled from follow-on schedule check
