[2023-08-22 14:36:46,630] {taskinstance.py:1179} INFO - Dependencies all met for <TaskInstance: entregable3.load_data_to_redshift manual__2023-08-22T14:36:35.688963+00:00 [queued]>
[2023-08-22 14:36:46,647] {taskinstance.py:1179} INFO - Dependencies all met for <TaskInstance: entregable3.load_data_to_redshift manual__2023-08-22T14:36:35.688963+00:00 [queued]>
[2023-08-22 14:36:46,649] {taskinstance.py:1376} INFO - 
--------------------------------------------------------------------------------
[2023-08-22 14:36:46,653] {taskinstance.py:1377} INFO - Starting attempt 1 of 6
[2023-08-22 14:36:46,654] {taskinstance.py:1378} INFO - 
--------------------------------------------------------------------------------
[2023-08-22 14:36:46,679] {taskinstance.py:1397} INFO - Executing <Task(PythonOperator): load_data_to_redshift> on 2023-08-22 14:36:35.688963+00:00
[2023-08-22 14:36:46,687] {standard_task_runner.py:52} INFO - Started process 3833 to run task
[2023-08-22 14:36:46,692] {standard_task_runner.py:79} INFO - Running: ['***', 'tasks', 'run', 'entregable3', 'load_data_to_redshift', 'manual__2023-08-22T14:36:35.688963+00:00', '--job-id', '38', '--raw', '--subdir', 'DAGS_FOLDER/entregable.py', '--cfg-path', '/tmp/tmp92ronlk9', '--error-file', '/tmp/tmpdmnxoohc']
[2023-08-22 14:36:46,694] {standard_task_runner.py:80} INFO - Job 38: Subtask load_data_to_redshift
[2023-08-22 14:36:46,800] {task_command.py:371} INFO - Running <TaskInstance: entregable3.load_data_to_redshift manual__2023-08-22T14:36:35.688963+00:00 [running]> on host eebeded14cb4
[2023-08-22 14:36:46,933] {taskinstance.py:1591} INFO - Exporting the following env vars:
AIRFLOW_CTX_DAG_OWNER=Yamil
AIRFLOW_CTX_DAG_ID=entregable3
AIRFLOW_CTX_TASK_ID=load_data_to_redshift
AIRFLOW_CTX_EXECUTION_DATE=2023-08-22T14:36:35.688963+00:00
AIRFLOW_CTX_TRY_NUMBER=1
AIRFLOW_CTX_DAG_RUN_ID=manual__2023-08-22T14:36:35.688963+00:00
[2023-08-22 14:36:50,188] {taskinstance.py:1909} ERROR - Task failed with exception
Traceback (most recent call last):
  File "/home/airflow/.local/lib/python3.7/site-packages/airflow/operators/python.py", line 171, in execute
    return_value = self.execute_callable()
  File "/home/airflow/.local/lib/python3.7/site-packages/airflow/operators/python.py", line 189, in execute_callable
    return self.python_callable(*self.op_args, **self.op_kwargs)
  File "/opt/airflow/dags/entregable.py", line 67, in load
    load_data_to_redshift(df_transformed, table_name, schema_name, db_username, db_password, db_name, db_host, db_port)
  File "/opt/airflow/dags/funciones.py", line 96, in load_data_to_redshift
    df_no_duplicates = df_final[~df_final['id'].isin(existing_ids)]
TypeError: 'NoneType' object is not subscriptable
[2023-08-22 14:36:50,256] {taskinstance.py:1420} INFO - Marking task as UP_FOR_RETRY. dag_id=entregable3, task_id=load_data_to_redshift, execution_date=20230822T143635, start_date=20230822T143646, end_date=20230822T143650
[2023-08-22 14:36:50,307] {standard_task_runner.py:97} ERROR - Failed to execute job 38 for task load_data_to_redshift ('NoneType' object is not subscriptable; 3833)
[2023-08-22 14:36:50,368] {local_task_job.py:156} INFO - Task exited with return code 1
[2023-08-22 14:36:50,491] {local_task_job.py:273} INFO - 0 downstream tasks scheduled from follow-on schedule check
