[2023-08-22 17:17:57,098] {taskinstance.py:1179} INFO - Dependencies all met for <TaskInstance: entregable3.load_data_to_redshift manual__2023-08-22T14:28:37.049234+00:00 [queued]>
[2023-08-22 17:17:57,134] {taskinstance.py:1179} INFO - Dependencies all met for <TaskInstance: entregable3.load_data_to_redshift manual__2023-08-22T14:28:37.049234+00:00 [queued]>
[2023-08-22 17:17:57,150] {taskinstance.py:1376} INFO - 
--------------------------------------------------------------------------------
[2023-08-22 17:17:57,151] {taskinstance.py:1377} INFO - Starting attempt 4 of 6
[2023-08-22 17:17:57,152] {taskinstance.py:1378} INFO - 
--------------------------------------------------------------------------------
[2023-08-22 17:17:57,228] {taskinstance.py:1397} INFO - Executing <Task(PythonOperator): load_data_to_redshift> on 2023-08-22 14:28:37.049234+00:00
[2023-08-22 17:17:57,243] {standard_task_runner.py:52} INFO - Started process 14569 to run task
[2023-08-22 17:17:57,256] {standard_task_runner.py:79} INFO - Running: ['***', 'tasks', 'run', 'entregable3', 'load_data_to_redshift', 'manual__2023-08-22T14:28:37.049234+00:00', '--job-id', '64', '--raw', '--subdir', 'DAGS_FOLDER/entregable.py', '--cfg-path', '/tmp/tmp28uzzspu', '--error-file', '/tmp/tmpzl0uo03r']
[2023-08-22 17:17:57,259] {standard_task_runner.py:80} INFO - Job 64: Subtask load_data_to_redshift
[2023-08-22 17:17:57,450] {task_command.py:371} INFO - Running <TaskInstance: entregable3.load_data_to_redshift manual__2023-08-22T14:28:37.049234+00:00 [running]> on host eebeded14cb4
[2023-08-22 17:17:57,698] {taskinstance.py:1591} INFO - Exporting the following env vars:
AIRFLOW_CTX_DAG_OWNER=Yamil
AIRFLOW_CTX_DAG_ID=entregable3
AIRFLOW_CTX_TASK_ID=load_data_to_redshift
AIRFLOW_CTX_EXECUTION_DATE=2023-08-22T14:28:37.049234+00:00
AIRFLOW_CTX_TRY_NUMBER=4
AIRFLOW_CTX_DAG_RUN_ID=manual__2023-08-22T14:28:37.049234+00:00
[2023-08-22 17:17:57,703] {taskinstance.py:1909} ERROR - Task failed with exception
Traceback (most recent call last):
  File "/home/airflow/.local/lib/python3.7/site-packages/airflow/operators/python.py", line 171, in execute
    return_value = self.execute_callable()
  File "/home/airflow/.local/lib/python3.7/site-packages/airflow/operators/python.py", line 189, in execute_callable
    return self.python_callable(*self.op_args, **self.op_kwargs)
  File "/opt/airflow/dags/entregable.py", line 55, in load
    df_transformed = df_final
NameError: name 'df_final' is not defined
[2023-08-22 17:17:57,760] {taskinstance.py:1420} INFO - Marking task as UP_FOR_RETRY. dag_id=entregable3, task_id=load_data_to_redshift, execution_date=20230822T142837, start_date=20230822T171757, end_date=20230822T171757
[2023-08-22 17:17:57,846] {standard_task_runner.py:97} ERROR - Failed to execute job 64 for task load_data_to_redshift (name 'df_final' is not defined; 14569)
[2023-08-22 17:17:57,892] {local_task_job.py:156} INFO - Task exited with return code 1
[2023-08-22 17:17:57,978] {local_task_job.py:273} INFO - 0 downstream tasks scheduled from follow-on schedule check
[2023-08-22 17:17:58,015] {dagrun.py:1081} ERROR - Failed to get task '<TaskInstance: entregable3.transform_data manual__2023-08-22T14:28:37.049234+00:00 [removed]>' for dag 'entregable3'. Marking it as removed.
[2023-08-22 17:17:58,023] {dagrun.py:1081} ERROR - Failed to get task '<TaskInstance: entregable3.get_data_from_api manual__2023-08-22T14:28:37.049234+00:00 [removed]>' for dag 'entregable3'. Marking it as removed.
